Workbook

Sheet ORIGINAL
A1: Product | B1: Current price | C1: old price | D1: Discount | E1: Review | F1: Ratingd
A2: 115 Piece Set Of Multifunctional Precision Screwdrivers | B2: KSh 950 | C2: KSh 1,525 | D2: 0.38 | E2: -2 | F2: 4.5 out of 5
A3: Metal Decorative Hooks Key Hangers Entryway Wall Hooks Towel Hooks - Home | B3: KSh 527 | C3: KSh 999 | D3: 0.47 | E3: -14 | F3: 4.1 out of 5
A4: Portable Mini Cordless Car Vacuum Cleaner - Blue | B4: KSh 2,199 | C4: KSh 2,923 | D4: 0.25 | E4: -24 | F4: 4.6 out of 5
A5: Weighing Scale Digital Bathroom Body Fat Scale USB-Black | B5: KSh 1,580 | C5: KSh 2,499 | D5: 0.37 | E5: -7 | F5: 4.7 out of 5
A6: Portable Home Small Air Humidifier 3-Speed Fan - Green | B6: KSh 1,740 | C6: KSh 2,356 | D6: 0.26 | E6: -5 | F6: 4.8 out of 5
A7: 220V 60W Electric Soldering Iron Kits With Tools, Tips, And Multimeter | B7: KSh 2,999 | C7: KSh 3,290 | D7: 0.09 | E7: -15 | F7: 4 out of 5
A8: 137 Pieces Cake Decorating Tool Set Baking Supplies | B8: KSh 2,319 | C8: KSh 3,032 | D8: 0.24 | E8: -55 | F8: 4.6 out of 5
A9: Desk Foldable Fan Adjustable Fan Strong Wind 3 Gear Usb | B9: KSh 988 | C9: KSh 1,580 | D9: 0.37 | E9: -2 | F9: 4 out of 5
A10: LASA FOLDING TABLE SERVING STAND | B10: KSh 1,274 | C10: KSh 2,800 | D10: 0.55 | E10: -5 | F10: 4.8 out of 5
A11: 13 In 1 Home Repair Tools Box Kit Set | B11: KSh 1,600 | C11: KSh 2,929 | D11: 0.45 | E11: -5 | F11: 3.8 out of 5
A12: Genebre 115 In 1 Screwdriver Repairing Tool Set For IPhone Cellphone Hand Tool | B12: KSh 799 | C12: KSh 999 | D12: 0.2 | E12: -12 | F12: 4.1 out of 5
A13: 100 Pcs Crochet Hook Tool Set Knitting Hook Set With Box | B13: KSh 990 | C13: KSh 1,500 | D13: 0.34 | E13: -39 | F13: 4.7 out of 5
... A22: 3PCS Single Head Knitting Crochet Sweater Needle Set | B22: KSh 38 | C22: KSh 80 | D22: 0.53 | E22: -13 | F22: 3.3 out of 5
A23: 4pcs Bathroom/Kitchen Towel Rack,Roll Paper Holder,Towel Bars,Hook | B23: KSh 1,860 | C23: KSh 3,220 | D23: 0.42
A24: LED Romantic Spaceship Starry Sky Projector,Children's Bedroom Night Light-Blue | B24: KSh 880 | C24: KSh 1,350 | D24: 0.35 | E24: -6 | F24: 4 out of 5
A25: Foldable Overbed Table/Desk | B25: KSh 1,650 | C25: KSh 2,150 | D25: 0.23 | E25: -14 | F25: 4.4 out of 5
A26: LASA 3 Tier Bamboo Shoe Bench Storage Shelf | B26: KSh 2,048 | C26: KSh 4,500 | D26: 0.54 | E26: -7 | F26: 4.3 out of 5
A27: Electronic Digital Display Vernier Caliper | B27: KSh 420 | C27: KSh 647 | D27: 0.35 | E27: -49 | F27: 4.6 out of 5
A28: Portable Wardrobe Nonwoven With 3 Hanging Rods And 6 Storage Shelves | B28: KSh 2,880 | C28: KSh 3,520 | D28: 0.18 | E28: -12 | F28: 3.8 out of 5
A29: 12 Litre Black Insulated Lunch Box | B29: KSh 1,350 | C29: KSh 1,990 | D29: 0.32 | E29: -13 | F29: 3.8 out of 5
A30: 52 Pieces Cake Decorating Tool Set Gift Kit Baking Supplies | B30: KSh 1,758 | C30: KSh 2,499 | D30: 0.3 | E30: -20 | F30: 4.1 out of 5
A31: MultiFunctional Storage Rack Multi-layer Bookshelf | B31: KSh 2,200 | C31: KSh 4,080 | D31: 0.46
A32: Exfoliate And Exfoliate Face Towel - Black | B32: KSh 185 | C32: KSh 382 | D32: 0.52 | E32: -9 | F32: 4.3 out of 5
A33: 12 Litre Insulated Lunch Box Grey | B33: KSh 980 | C33: KSh 1,490 | D33: 0.34 | E33: -12 | F33: 4.7 out of 5
A34: LED Eye Protection Desk Lamp , Study, Reading, USB Fan - Double Pen Holder | B34: KSh 1,820 | C34: KSh 3,490 | D34: 0.48 | E34: -9 | F34: 4.3 out of 5
A35: 53Pcs/Set Yarn Knitting Crochet Hooks With Bag - Fortune Cat | B35: KSh 1,940 | C35: KSh 2,650 | D35: 0.27 | E35: -20 | F35: 4.7 out of 5
A36: 53 Pieces/Set Yarn Knitting Crochet Hooks With Bag - Pansies | B36: KSh 1,980 | C36: KSh 2,699 | D36: 0.27 | E36: -32 | F36: 4.5 out of 5
A37: DIY File Folder, Office Drawer File Holder, Pen Holder, Desktop Storage Rack | B37: KSh 1,620 | C37: KSh 2,690 | D37: 0.4 | E37: -1 | F37: 5 out of 5
A38: Classic Black Cat Cotton Hemp Pillow Case For Home Car | B38: KSh 171 | C38: KSh 360 | D38: 0.53 | E38: -2 | F38: 5 out of 5
A39: Punch-free Great Load Bearing Bathroom Storage Rack Wall Shelf-White | B39: KSh 389 | C39: KSh 656 | D39: 0.41 | E39: -36 | F39: 4.3 out of 5
A40: 1/2/3 Seater Elastic Sofa Cover,Living Room/Home Decor Chair Cover-Grey | B40: KSh 1,620 - KSh 1,980 | C40: KSh 2,200 - KSh 3,200 | D40: 0.38 | E40: -2 | F40: 4.5 out of 5
A41: LASA Stainless Steel Double Wall Mount Soap Dispenser - 500ml | B41: KSh 2,750 | C41: KSh 4,471 | D41: 0.38
A42: 4M Float Switch Water Level Controller -Water Tank | B42: KSh 475 | C42: KSh 931 | D42: 0.49
A43: Modern Sofa Throw Pillow Cover-45x45cm-Blue&Red | B43: KSh 238 | C43: KSh 476 | D43: 0.5
A44: Balloon Insert, Birthday Party Balloon Set, PU Leather | B44: KSh 610 | C44: KSh 1,060 | D44: 0.42
A45: Balloon Insert, Birthday Party Balloon Set, PU Leather | B45: KSh 610 | C45: KSh 1,060 | D45: 0.42
A46: Shower Cap Wide Elastic Band Cover Reusable Bashroom Cap | B46: KSh 2,132 | C46: KSh 2,169 | D46: 0.02
A47: Christmas Elk Fence Yard Lawn Decorations Cute For Holidays | B47: KSh 999 | C47: KSh 2,000 | D47: 0.5
A48: 60W Hot Melt Glue Sprayer - Efficient And Stable Glue Dispensing | B48: KSh 1,190 | C48: KSh 1,785 | D48: 0.33
...

Sheet Cleaned Data
A1: Product | B1: Current price | C1: old price | D1: Savings | E1: Discount | F1: Discount % | G1: Review | H1: Has Reviews | I1: Ratings | J1: RANK TOP PERFORMER | K1: RANK NEEDS ATTENTION
A2: 115 Piece Set Of Multifunctional Precision Screwdrivers | B2: 950 | C2: 1525 | D2: =C2-B2 -> 575 | E2: 0.38 | F2: =E2*100 -> 38 | G2: 2 | H2: =IF(ISBLANK(G2),"NO","YES") -> YES | I2: 4.5 | J2: =IF(AND(I2<>"", I2>=DASHBOARD!$B$16), G2+ROW()/100000, "") -> 2.00002 | K2: =IF(AND(F2>=DASHBOARD!$B$31,OR(G2="",G2<=DASHBOARD!$E$31)),F2+ROW()/100000,"")
A3: Metal Decorative Hooks Key Hangers Entryway Wall Hooks Towel Hooks - Home | B3: 527 | C3: 999 | D3: =C3-B3 -> 472 | E3: 0.47 | F3: =E3*100 -> 47 | G3: 14 | H3: =IF(ISBLANK(G3),"NO","YES") -> YES | I3: 4.1 | J3: =IF(AND(I3<>"", I3>=DASHBOARD!$B$16), G3+ROW()/100000, "") | K3: =IF(AND(F3>=DASHBOARD!$B$31,OR(G3="",G3<=DASHBOARD!$E$31)),F3+ROW()/100000,"")
A4: Portable Mini Cordless Car Vacuum Cleaner - Blue | B4: 2199 | C4: 2923 | D4: =C4-B4 -> 724 | E4: 0.25 | F4: =E4*100 -> 25 | G4: 24 | H4: =IF(ISBLANK(G4),"NO","YES") -> YES | I4: 4.6 | J4: =IF(AND(I4<>"", I4>=DASHBOARD!$B$16), G4+ROW()/100000, "") -> 24.00004 | K4: =IF(AND(F4>=DASHBOARD!$B$31,OR(G4="",G4<=DASHBOARD!$E$31)),F4+ROW()/100000,"")
A5: Weighing Scale Digital Bathroom Body Fat Scale USB-Black | B5: 1580 | C5: 2499 | D5: =C5-B5 -> 919 | E5: 0.37 | F5: =E5*100 -> 37 | G5: 7 | H5: =IF(ISBLANK(G5),"NO","YES") -> YES | I5: 4.7 | J5: =IF(AND(I5<>"", I5>=DASHBOARD!$B$16), G5+ROW()/100000, "") -> 7.00005 | K5: =IF(AND(F5>=DASHBOARD!$B$31,OR(G5="",G5<=DASHBOARD!$E$31)),F5+ROW()/100000,"")
A6: Portable Home Small Air Humidifier 3-Speed Fan - Green | B6: 1740 | C6: 2356 | D6: =C6-B6 -> 616 | E6: 0.26 | F6: =E6*100 -> 26 | G6: 5 | H6: =IF(ISBLANK(G6),"NO","YES") -> YES | I6: 4.8 | J6: =IF(AND(I6<>"", I6>=DASHBOARD!$B$16), G6+ROW()/100000, "") -> 5.00006 | K6: =IF(AND(F6>=DASHBOARD!$B$31,OR(G6="",G6<=DASHBOARD!$E$31)),F6+ROW()/100000,"")
A7: 220V 60W Electric Soldering Iron Kits With Tools, Tips, And Multimeter | B7: 2999 | C7: 3290 | D7: =C7-B7 -> 291 | E7: 0.09 | F7: =E7*100 -> 9 | G7: 15 | H7: =IF(ISBLANK(G7),"NO","YES") -> YES | I7: 4 | J7: =IF(AND(I7<>"", I7>=DASHBOARD!$B$16), G7+ROW()/100000, "") | K7: =IF(AND(F7>=DASHBOARD!$B$31,OR(G7="",G7<=DASHBOARD!$E$31)),F7+ROW()/100000,"")
A8: 137 Pieces Cake Decorating Tool Set Baking Supplies | B8: 2319 | C8: 3032 | D8: =C8-B8 -> 713 | E8: 0.24 | F8: =E8*100 -> 24 | G8: 55 | H8: =IF(ISBLANK(G8),"NO","YES") -> YES | I8: 4.6 | J8: =IF(AND(I8<>"", I8>=DASHBOARD!$B$16), G8+ROW()/100000, "") -> 55.00008 | K8: =IF(AND(F8>=DASHBOARD!$B$31,OR(G8="",G8<=DASHBOARD!$E$31)),F8+ROW()/100000,"")
A9: Desk Foldable Fan Adjustable Fan Strong Wind 3 Gear Usb | B9: 988 | C9: 1580 | D9: =C9-B9 -> 592 | E9: 0.37 | F9: =E9*100 -> 37 | G9: 2 | H9: =IF(ISBLANK(G9),"NO","YES") -> YES | I9: 4 | J9: =IF(AND(I9<>"", I9>=DASHBOARD!$B$16), G9+ROW()/100000, "") | K9: =IF(AND(F9>=DASHBOARD!$B$31,OR(G9="",G9<=DASHBOARD!$E$31)),F9+ROW()/100000,"")
A10: LASA FOLDING TABLE SERVING STAND | B10: 1274 | C10: 2800 | D10: =C10-B10 -> 1526 | E10: 0.55 | F10: =E10*100 -> 55 | G10: 5 | H10: =IF(ISBLANK(G10),"NO","YES") -> YES | I10: 4.8 | J10: =IF(AND(I10<>"", I10>=DASHBOARD!$B$16), G10+ROW()/100000, "") -> 5.0001 | K10: =IF(AND(F10>=DASHBOARD!$B$31,OR(G10="",G10<=DASHBOARD!$E$31)),F10+ROW()/100000,"")
A11: 13 In 1 Home Repair Tools Box Kit Set | B11: 1600 | C11: 2929 | D11: =C11-B11 -> 1329 | E11: 0.45 | F11: =E11*100 -> 45 | G11: 5 | H11: =IF(ISBLANK(G11),"NO","YES") -> YES | I11: 3.8 | J11: =IF(AND(I11<>"", I11>=DASHBOARD!$B$16), G11+ROW()/100000, "") | K11: =IF(AND(F11>=DASHBOARD!$B$31,OR(G11="",G11<=DASHBOARD!$E$31)),F11+ROW()/100000,"")
A12: Genebre 115 In 1 Screwdriver Repairing Tool Set For IPhone Cellphone Hand Tool | B12: 799 | C12: 999 | D12: =C12-B12 -> 200 | E12: 0.2 | F12: =E12*100 -> 20 | G12: 12 | H12: =IF(ISBLANK(G12),"NO","YES") -> YES | I12: 4.1 | J12: =IF(AND(I12<>"", I12>=DASHBOARD!$B$16), G12+ROW()/100000, "") | K12: =IF(AND(F12>=DASHBOARD!$B$31,OR(G12="",G12<=DASHBOARD!$E$31)),F12+ROW()/100000,"")
A13: 100 Pcs Crochet Hook Tool Set Knitting Hook Set With Box | B13: 990 | C13: 1500 | D13: =C13-B13 -> 510 | E13: 0.34 | F13: =E13*100 -> 34 | G13: 39 | H13: =IF(ISBLANK(G13),"NO","YES") -> YES | I13: 4.7 | J13: =IF(AND(I13<>"", I13>=DASHBOARD!$B$16), G13+ROW()/100000, "") -> 39.00013 | K13: =IF(AND(F13>=DASHBOARD!$B$31,OR(G13="",G13<=DASHBOARD!$E$31)),F13+ROW()/100000,"")
... A22: 3PCS Single Head Knitting Crochet Sweater Needle Set | B22: 38 | C22: 80 | D22: =C22-B22 -> 42 | E22: 0.53 | F22: =E22*100 -> 53 | G22: 13 | H22: =IF(ISBLANK(G22),"NO","YES") -> YES | I22: 3.3 | J22: =IF(AND(I22<>"", I22>=DASHBOARD!$B$16), G22+ROW()/100000, "") | K22: =IF(AND(F22>=DASHBOARD!$B$31,OR(G22="",G22<=DASHBOARD!$E$31)),F22+ROW()/100000,"")
A23: 4pcs Bathroom/Kitchen Towel Rack,Roll Paper Holder,Towel Bars,Hook | B23: 1860 | C23: 3220 | D23: =C23-B23 -> 1360 | E23: 0.42 | F23: =E23*100 -> 42 | H23: =IF(ISBLANK(G23),"NO","YES") -> NO | J23: =IF(AND(I23<>"", I23>=DASHBOARD!$B$16), G23+ROW()/100000, "") | K23: =IF(AND(F23>=DASHBOARD!$B$31,OR(G23="",G23<=DASHBOARD!$E$31)),F23+ROW()/100000,"") -> 42.00023
A24: LED Romantic Spaceship Starry Sky Projector,Children's Bedroom Night Light-Blue | B24: 880 | C24: 1350 | D24: =C24-B24 -> 470 | E24: 0.35 | F24: =E24*100 -> 35 | G24: 6 | H24: =IF(ISBLANK(G24),"NO","YES") -> YES | I24: 4 | J24: =IF(AND(I24<>"", I24>=DASHBOARD!$B$16), G24+ROW()/100000, "") | K24: =IF(AND(F24>=DASHBOARD!$B$31,OR(G24="",G24<=DASHBOARD!$E$31)),F24+ROW()/100000,"")
A25: Foldable Overbed Table/Desk | B25: 1650 | C25: 2150 | D25: =C25-B25 -> 500 | E25: 0.23 | F25: =E25*100 -> 23 | G25: 14 | H25: =IF(ISBLANK(G25),"NO","YES") -> YES | I25: 4.4 | J25: =IF(AND(I25<>"", I25>=DASHBOARD!$B$16), G25+ROW()/100000, "") | K25: =IF(AND(F25>=DASHBOARD!$B$31,OR(G25="",G25<=DASHBOARD!$E$31)),F25+ROW()/100000,"")
A26: LASA 3 Tier Bamboo Shoe Bench Storage Shelf | B26: 2048 | C26: 4500 | D26: =C26-B26 -> 2452 | E26: 0.54 | F26: =E26*100 -> 54 | G26: 7 | H26: =IF(ISBLANK(G26),"NO","YES") -> YES | I26: 4.3 | J26: =IF(AND(I26<>"", I26>=DASHBOARD!$B$16), G26+ROW()/100000, "") | K26: =IF(AND(F26>=DASHBOARD!$B$31,OR(G26="",G26<=DASHBOARD!$E$31)),F26+ROW()/100000,"")
A27: Electronic Digital Display Vernier Caliper | B27: 420 | C27: 647 | D27: =C27-B27 -> 227 | E27: 0.35 | F27: =E27*100 -> 35 | G27: 49 | H27: =IF(ISBLANK(G27),"NO","YES") -> YES | I27: 4.6 | J27: =IF(AND(I27<>"", I27>=DASHBOARD!$B$16), G27+ROW()/100000, "") -> 49.00027 | K27: =IF(AND(F27>=DASHBOARD!$B$31,OR(G27="",G27<=DASHBOARD!$E$31)),F27+ROW()/100000,"")
A28: Portable Wardrobe Nonwoven With 3 Hanging Rods And 6 Storage Shelves | B28: 2880 | C28: 3520 | D28: =C28-B28 -> 640 | E28: 0.18 | F28: =E28*100 -> 18 | G28: 12 | H28: =IF(ISBLANK(G28),"NO","YES") -> YES | I28: 3.8 | J28: =IF(AND(I28<>"", I28>=DASHBOARD!$B$16), G28+ROW()/100000, "") | K28: =IF(AND(F28>=DASHBOARD!$B$31,OR(G28="",G28<=DASHBOARD!$E$31)),F28+ROW()/100000,"")
A29: 12 Litre Black Insulated Lunch Box | B29: 1350 | C29: 1990 | D29: =C29-B29 -> 640 | E29: 0.32 | F29: =E29*100 -> 32 | G29: 13 | H29: =IF(ISBLANK(G29),"NO","YES") -> YES | I29: 3.8 | J29: =IF(AND(I29<>"", I29>=DASHBOARD!$B$16), G29+ROW()/100000, "") | K29: =IF(AND(F29>=DASHBOARD!$B$31,OR(G29="",G29<=DASHBOARD!$E$31)),F29+ROW()/100000,"")
A30: 52 Pieces Cake Decorating Tool Set Gift Kit Baking Supplies | B30: 1758 | C30: 2499 | D30: =C30-B30 -> 741 | E30: 0.3 | F30: =E30*100 -> 30 | G30: 20 | H30: =IF(ISBLANK(G30),"NO","YES") -> YES | I30: 4.1 | J30: =IF(AND(I30<>"", I30>=DASHBOARD!$B$16), G30+ROW()/100000, "") | K30: =IF(AND(F30>=DASHBOARD!$B$31,OR(G30="",G30<=DASHBOARD!$E$31)),F30+ROW()/100000,"")
A31: MultiFunctional Storage Rack Multi-layer Bookshelf | B31: 2200 | C31: 4080 | D31: =C31-B31 -> 1880 | E31: 0.46 | F31: =E31*100 -> 46 | H31: =IF(ISBLANK(G31),"NO","YES") -> NO | J31: =IF(AND(I31<>"", I31>=DASHBOARD!$B$16), G31+ROW()/100000, "") | K31: =IF(AND(F31>=DASHBOARD!$B$31,OR(G31="",G31<=DASHBOARD!$E$31)),F31+ROW()/100000,"") -> 46.00031
A32: Exfoliate And Exfoliate Face Towel - Black | B32: 185 | C32: 382 | D32: =C32-B32 -> 197 | E32: 0.52 | F32: =E32*100 -> 52 | G32: 9 | H32: =IF(ISBLANK(G32),"NO","YES") -> YES | I32: 4.3 | J32: =IF(AND(I32<>"", I32>=DASHBOARD!$B$16), G32+ROW()/100000, "") | K32: =IF(AND(F32>=DASHBOARD!$B$31,OR(G32="",G32<=DASHBOARD!$E$31)),F32+ROW()/100000,"")
A33: 12 Litre Insulated Lunch Box Grey | B33: 980 | C33: 1490 | D33: =C33-B33 -> 510 | E33: 0.34 | F33: =E33*100 -> 34 | G33: 12 | H33: =IF(ISBLANK(G33),"NO","YES") -> YES | I33: 4.7 | J33: =IF(AND(I33<>"", I33>=DASHBOARD!$B$16), G33+ROW()/100000, "") -> 12.00033 | K33: =IF(AND(F33>=DASHBOARD!$B$31,OR(G33="",G33<=DASHBOARD!$E$31)),F33+ROW()/100000,"")
A34: LED Eye Protection Desk Lamp , Study, Reading, USB Fan - Double Pen Holder | B34: 1820 | C34: 3490 | D34: =C34-B34 -> 1670 | E34: 0.48 | F34: =E34*100 -> 48 | G34: 9 | H34: =IF(ISBLANK(G34),"NO","YES") -> YES | I34: 4.3 | J34: =IF(AND(I34<>"", I34>=DASHBOARD!$B$16), G34+ROW()/100000, "") | K34: =IF(AND(F34>=DASHBOARD!$B$31,OR(G34="",G34<=DASHBOARD!$E$31)),F34+ROW()/100000,"")
A35: 53Pcs/Set Yarn Knitting Crochet Hooks With Bag - Fortune Cat | B35: 1940 | C35: 2650 | D35: =C35-B35 -> 710 | E35: 0.27 | F35: =E35*100 -> 27 | G35: 20 | H35: =IF(ISBLANK(G35),"NO","YES") -> YES | I35: 4.7 | J35: =IF(AND(I35<>"", I35>=DASHBOARD!$B$16), G35+ROW()/100000, "") -> 20.00035 | K35: =IF(AND(F35>=DASHBOARD!$B$31,OR(G35="",G35<=DASHBOARD!$E$31)),F35+ROW()/100000,"")
A36: 53 Pieces/Set Yarn Knitting Crochet Hooks With Bag - Pansies | B36: 1980 | C36: 2699 | D36: =C36-B36 -> 719 | E36: 0.27 | F36: =E36*100 -> 27 | G36: 32 | H36: =IF(ISBLANK(G36),"NO","YES") -> YES | I36: 4.5 | J36: =IF(AND(I36<>"", I36>=DASHBOARD!$B$16), G36+ROW()/100000, "") -> 32.00036 | K36: =IF(AND(F36>=DASHBOARD!$B$31,OR(G36="",G36<=DASHBOARD!$E$31)),F36+ROW()/100000,"")
A37: DIY File Folder, Office Drawer File Holder, Pen Holder, Desktop Storage Rack | B37: 1620 | C37: 2690 | D37: =C37-B37 -> 1070 | E37: 0.4 | F37: =E37*100 -> 40 | G37: 1 | H37: =IF(ISBLANK(G37),"NO","YES") -> YES | I37: 5 | J37: =IF(AND(I37<>"", I37>=DASHBOARD!$B$16), G37+ROW()/100000, "") -> 1.00037 | K37: =IF(AND(F37>=DASHBOARD!$B$31,OR(G37="",G37<=DASHBOARD!$E$31)),F37+ROW()/100000,"") -> 40.00037
A38: Classic Black Cat Cotton Hemp Pillow Case For Home Car | B38: 171 | C38: 360 | D38: =C38-B38 -> 189 | E38: 0.53 | F38: =E38*100 -> 53 | G38: 2 | H38: =IF(ISBLANK(G38),"NO","YES") -> YES | I38: 5 | J38: =IF(AND(I38<>"", I38>=DASHBOARD!$B$16), G38+ROW()/100000, "") -> 2.00038 | K38: =IF(AND(F38>=DASHBOARD!$B$31,OR(G38="",G38<=DASHBOARD!$E$31)),F38+ROW()/100000,"") -> 53.00038
A39: Punch-free Great Load Bearing Bathroom Storage Rack Wall Shelf-White | B39: 389 | C39: 656 | D39: =C39-B39 -> 267 | E39: 0.41 | F39: =E39*100 -> 41 | G39: 36 | H39: =IF(ISBLANK(G39),"NO","YES") -> YES | I39: 4.3 | J39: =IF(AND(I39<>"", I39>=DASHBOARD!$B$16), G39+ROW()/100000, "") | K39: =IF(AND(F39>=DASHBOARD!$B$31,OR(G39="",G39<=DASHBOARD!$E$31)),F39+ROW()/100000,"")
A40: 1/2/3 Seater Elastic Sofa Cover,Living Room/Home Decor Chair Cover-Grey | B40: 1800 | C40: 2700 | D40: =C40-B40 -> 900 | E40: 0.38 | F40: =E40*100 -> 38 | G40: 2 | H40: =IF(ISBLANK(G40),"NO","YES") -> YES | I40: 4.5 | J40: =IF(AND(I40<>"", I40>=DASHBOARD!$B$16), G40+ROW()/100000, "") -> 2.0004 | K40: =IF(AND(F40>=DASHBOARD!$B$31,OR(G40="",G40<=DASHBOARD!$E$31)),F40+ROW()/100000,"")
A41: LASA Stainless Steel Double Wall Mount Soap Dispenser - 500ml | B41: 2750 | C41: 4471 | D41: =C41-B41 -> 1721 | E41: 0.38 | F41: =E41*100 -> 38 | H41: =IF(ISBLANK(G41),"NO","YES") -> NO | J41: =IF(AND(I41<>"", I41>=DASHBOARD!$B$16), G41+ROW()/100000, "") | K41: =IF(AND(F41>=DASHBOARD!$B$31,OR(G41="",G41<=DASHBOARD!$E$31)),F41+ROW()/100000,"")
A42: 4M Float Switch Water Level Controller -Water Tank | B42: 475 | C42: 931 | D42: =C42-B42 -> 456 | E42: 0.49 | F42: =E42*100 -> 49 | H42: =IF(ISBLANK(G42),"NO","YES") -> NO | J42: =IF(AND(I42<>"", I42>=DASHBOARD!$B$16), G42+ROW()/100000, "") | K42: =IF(AND(F42>=DASHBOARD!$B$31,OR(G42="",G42<=DASHBOARD!$E$31)),F42+ROW()/100000,"") -> 49.00042
A43: Modern Sofa Throw Pillow Cover-45x45cm-Blue&Red | B43: 238 | C43: 476 | D43: =C43-B43 -> 238 | E43: 0.5 | F43: =E43*100 -> 50 | H43: =IF(ISBLANK(G43),"NO","YES") -> NO | J43: =IF(AND(I43<>"", I43>=DASHBOARD!$B$16), G43+ROW()/100000, "") | K43: =IF(AND(F43>=DASHBOARD!$B$31,OR(G43="",G43<=DASHBOARD!$E$31)),F43+ROW()/100000,"") -> 50.00043
A44: Balloon Insert, Birthday Party Balloon Set, PU Leather | B44: 610 | C44: 1060 | D44: =C44-B44 -> 450 | E44: 0.42 | F44: =E44*100 -> 42 | H44: =IF(ISBLANK(G44),"NO","YES") -> NO | J44: =IF(AND(I44<>"", I44>=DASHBOARD!$B$16), G44+ROW()/100000, "") | K44: =IF(AND(F44>=DASHBOARD!$B$31,OR(G44="",G44<=DASHBOARD!$E$31)),F44+ROW()/100000,"") -> 42.00044
A45: Balloon Insert, Birthday Party Balloon Set, PU Leather | B45: 610 | C45: 1060 | D45: =C45-B45 -> 450 | E45: 0.42 | F45: =E45*100 -> 42 | H45: =IF(ISBLANK(G45),"NO","YES") -> NO | J45: =IF(AND(I45<>"", I45>=DASHBOARD!$B$16), G45+ROW()/100000, "") | K45: =IF(AND(F45>=DASHBOARD!$B$31,OR(G45="",G45<=DASHBOARD!$E$31)),F45+ROW()/100000,"") -> 42.00045
A46: Shower Cap Wide Elastic Band Cover Reusable Bashroom Cap | B46: 2132 | C46: 2169 | D46: =C46-B46 -> 37 | E46: 0.02 | F46: =E46*100 -> 2 | H46: =IF(ISBLANK(G46),"NO","YES") -> NO | J46: =IF(AND(I46<>"", I46>=DASHBOARD!$B$16), G46+ROW()/100000, "") | K46: =IF(AND(F46>=DASHBOARD!$B$31,OR(G46="",G46<=DASHBOARD!$E$31)),F46+ROW()/100000,"")
A47: Christmas Elk Fence Yard Lawn Decorations Cute For Holidays | B47: 999 | C47: 2000 | D47: =C47-B47 -> 1001 | E47: 0.5 | F47: =E47*100 -> 50 | H47: =IF(ISBLANK(G47),"NO","YES") -> NO | J47: =IF(AND(I47<>"", I47>=DASHBOARD!$B$16), G47+ROW()/100000, "") | K47: =IF(AND(F47>=DASHBOARD!$B$31,OR(G47="",G47<=DASHBOARD!$E$31)),F47+ROW()/100000,"") -> 50.00047
A48: 60W Hot Melt Glue Sprayer - Efficient And Stable Glue Dispensing | B48: 1190 | C48: 1785 | D48: =C48-B48 -> 595 | E48: 0.33 | F48: =E48*100 -> 33 | H48: =IF(ISBLANK(G48),"NO","YES") -> NO | J48: =IF(AND(I48<>"", I48>=DASHBOARD!$B$16), G48+ROW()/100000, "") | K48: =IF(AND(F48>=DASHBOARD!$B$31,OR(G48="",G48<=DASHBOARD!$E$31)),F48+ROW()/100000,"")
...

Sheet DASHBOARD
A10: RELATIONSHIPS | B10: CORRELATION (r) | C10: READING
A11: Discount % vs. Number of Reviews | B11: =CORREL('Cleaned Data'!F2:F116,'Cleaned Data'!G2:G116) -> -0.13682272 | C11: =IF(B11="","n/a", IF(ABS(B11)<0.1,"No meaningful relationship", IF(B11>0,IF(ABS(B11)>0.5,"Strong positive","Weak/Moderate positive"), IF(ABS(B11)>0.5,"Strong negative","Weak/Moderate negative")))) -> Weak/Moderate negative
A12: Rating vs. Number of Reviews | B12: =CORREL('Cleaned Data'!I2:I116,'Cleaned Data'!G2:G116) -> 0.057209035 | C12: {=_xlfn.IFS(B12="", "n/a", B12>0.5, "Strong positive", B12>=0.1, "Weak/Moderate positive", B12>-0.1, "No meaningful relationship", B12>=-0.5, "Weak/Moderate negative", TRUE, "Strong negative")} -> No meaningful relationship
A13: Price vs Rating | B13: =CORREL('Cleaned Data'!B2:B116,'Cleaned Data'!I2:I116) -> 0.11009021 | C13: {=_xlfn.IFS(B13="", "n/a", B13>0.5, "Strong positive", B13>=0.1, "Weak/Moderate positive", B13>-0.1, "No meaningful relationship", B13>=-0.5, "Weak/Moderate negative", TRUE, "Strong negative")} -> Weak/Moderate positive
A15: TOP PERFORMING PRODUCTS:
A16: MINIMUM rating to qualify: | B16: 4.5 | D16: Show top : | E16: 10
A17: NUMBER | B17: PRODUCT | C17: RATING | D17: REVIEWS | E17: PRICE | F17: DISCOUNT%
A18: 1 | B18: =IF(OR($E$16<1,IFERROR(LARGE('Cleaned Data'!$J$2:$J$116,1),"")=""),"",INDEX('Cleaned Data'!$A$2:$A$116,MATCH(LARGE('Cleaned Data'!$J$2:$J$116,1),'Cleaned Data'!$J$2:$J$116,0))) -> 137 Pieces Cake Decorating Tool Set Baking Supplies | C18: =IF($B18="","",INDEX('Cleaned Data'!$I$2:$I$116,MATCH(LARGE('Cleaned Data'!$J$2:$J$116,1),'Cleaned Data'!$J$2:$J$116,0))) -> 4.6 | D18: =IF($B18="","",INDEX('Cleaned Data'!$G$2:$G$116,MATCH(LARGE('Cleaned Data'!$J$2:$J$116,1),'Cleaned Data'!$J$2:$J$116,0))) -> 55 | E18: =IF($B18="","",INDEX('Cleaned Data'!$B$2:$B$116,MATCH(LARGE('Cleaned Data'!$J$2:$J$116,1),'Cleaned Data'!$J$2:$J$116,0))) -> 2319 | F18: =IF($B18="","",INDEX('Cleaned Data'!$F$2:$F$116,MATCH(LARGE('Cleaned Data'!$J$2:$J$116,1),'Cleaned Data'!$J$2:$J$116,0))) -> 24
A19: 2 | B19: =IF(OR($E$16<2,IFERROR(LARGE('Cleaned Data'!$J$2:$J$116,2),"")=""),"",INDEX('Cleaned Data'!$A$2:$A$116,MATCH(LARGE('Cleaned Data'!$J$2:$J$116,2),'Cleaned Data'!$J$2:$J$116,0))) -> Electronic Digital Display Vernier Caliper | C19: =IF($B19="","",INDEX('Cleaned Data'!$I$2:$I$116,MATCH(LARGE('Cleaned Data'!$J$2:$J$116,2),'Cleaned Data'!$J$2:$J$116,0))) -> 4.6 | D19: =IF($B18="","",INDEX('Cleaned Data'!$G$2:$G$116,MATCH(LARGE('Cleaned Data'!$J$2:$J$116,2),'Cleaned Data'!$J$2:$J$116,0))) -> 49 | E19: =IF($B18="","",INDEX('Cleaned Data'!$B$2:$B$116,MATCH(LARGE('Cleaned Data'!$J$2:$J$116,2),'Cleaned Data'!$J$2:$J$116,0))) -> 420 | F19: =IF($B18="","",INDEX('Cleaned Data'!$F$2:$F$116,MATCH(LARGE('Cleaned Data'!$J$2:$J$116,2),'Cleaned Data'!$J$2:$J$116,0))) -> 35
A20: 3 | B20: =IF(OR($E$16<3,IFERROR(LARGE('Cleaned Data'!$J$2:$J$116,3),"")=""),"",INDEX('Cleaned Data'!$A$2:$A$116,MATCH(LARGE('Cleaned Data'!$J$2:$J$116,3),'Cleaned Data'!$J$2:$J$116,0))) -> 3D Waterproof EVA Plastic Shower Curtain 1.8*2Mtrs | C20: =IF($B20="","",INDEX('Cleaned Data'!$I$2:$I$116,MATCH(LARGE('Cleaned Data'!$J$2:$J$116,3),'Cleaned Data'!$J$2:$J$116,0))) -> 4.6 | D20: =IF($B18="","",INDEX('Cleaned Data'!$G$2:$G$116,MATCH(LARGE('Cleaned Data'!$J$2:$J$116,3),'Cleaned Data'!$J$2:$J$116,0))) -> 44 | E20: =IF($B18="","",INDEX('Cleaned Data'!$B$2:$B$116,MATCH(LARGE('Cleaned Data'!$J$2:$J$116,3),'Cleaned Data'!$J$2:$J$116,0))) -> 998 | F20: =IF($B18="","",INDEX('Cleaned Data'!$F$2:$F$116,MATCH(LARGE('Cleaned Data'!$J$2:$J$116,3),'Cleaned Data'!$J$2:$J$116,0))) -> 49
A21: 4 | B21: =IF(OR($E$16<4,IFERROR(LARGE('Cleaned Data'!$J$2:$J$116,4),"")=""),"",INDEX('Cleaned Data'!$A$2:$A$116,MATCH(LARGE('Cleaned Data'!$J$2:$J$116,4),'Cleaned Data'!$J$2:$J$116,0))) -> 100 Pcs Crochet Hook Tool Set Knitting Hook Set With Box | C21: =IF($B21="","",INDEX('Cleaned Data'!$I$2:$I$116,MATCH(LARGE('Cleaned Data'!$J$2:$J$116,4),'Cleaned Data'!$J$2:$J$116,0))) -> 4.7 | D21: =IF($B18="","",INDEX('Cleaned Data'!$G$2:$G$116,MATCH(LARGE('Cleaned Data'!$J$2:$J$116,4),'Cleaned Data'!$J$2:$J$116,0))) -> 39 | E21: =IF($B18="","",INDEX('Cleaned Data'!$B$2:$B$116,MATCH(LARGE('Cleaned Data'!$J$2:$J$116,4),'Cleaned Data'!$J$2:$J$116,0))) -> 990 | F21: =IF($B18="","",INDEX('Cleaned Data'!$F$2:$F$116,MATCH(LARGE('Cleaned Data'!$J$2:$J$116,4),'Cleaned Data'!$J$2:$J$116,0))) -> 34
A22: 5 | B22: =IF(OR($E$16<5,IFERROR(LARGE('Cleaned Data'!$J$2:$J$116,5),"")=""),"",INDEX('Cleaned Data'!$A$2:$A$116,MATCH(LARGE('Cleaned Data'!$J$2:$J$116,5),'Cleaned Data'!$J$2:$J$116,0))) -> 53 Pieces/Set Yarn Knitting Crochet Hooks With Bag - Pansies | C22: =IF($B22="","",INDEX('Cleaned Data'!$I$2:$I$116,MATCH(LARGE('Cleaned Data'!$J$2:$J$116,5),'Cleaned Data'!$J$2:$J$116,0))) -> 4.5 | D22: =IF($B18="","",INDEX('Cleaned Data'!$G$2:$G$116,MATCH(LARGE('Cleaned Data'!$J$2:$J$116,5),'Cleaned Data'!$J$2:$J$116,0))) -> 32 | E22: =IF($B18="","",INDEX('Cleaned Data'!$B$2:$B$116,MATCH(LARGE('Cleaned Data'!$J$2:$J$116,5),'Cleaned Data'!$J$2:$J$116,0))) -> 1980 | F22: =IF($B18="","",INDEX('Cleaned Data'!$F$2:$F$116,MATCH(LARGE('Cleaned Data'!$J$2:$J$116,5),'Cleaned Data'!$J$2:$J$116,0))) -> 27
A23: 6 | B23: =IF(OR($E$16<6,IFERROR(LARGE('Cleaned Data'!$J$2:$J$116,6),"")=""),"",INDEX('Cleaned Data'!$A$2:$A$116,MATCH(LARGE('Cleaned Data'!$J$2:$J$116,6),'Cleaned Data'!$J$2:$J$116,0))) -> Portable Mini Cordless Car Vacuum Cleaner - Blue | C23: =IF($B23="","",INDEX('Cleaned Data'!$I$2:$I$116,MATCH(LARGE('Cleaned Data'!$J$2:$J$116,6),'Cleaned Data'!$J$2:$J$116,0))) -> 4.6 | D23: =IF($B18="","",INDEX('Cleaned Data'!$G$2:$G$116,MATCH(LARGE('Cleaned Data'!$J$2:$J$116,6),'Cleaned Data'!$J$2:$J$116,0))) -> 24 | E23: =IF($B18="","",INDEX('Cleaned Data'!$B$2:$B$116,MATCH(LARGE('Cleaned Data'!$J$2:$J$116,6),'Cleaned Data'!$J$2:$J$116,0))) -> 2199 | F23: =IF($B18="","",INDEX('Cleaned Data'!$F$2:$F$116,MATCH(LARGE('Cleaned Data'!$J$2:$J$116,6),'Cleaned Data'!$J$2:$J$116,0))) -> 25
A24: 7 | B24: =IF(OR($E$16<7,IFERROR(LARGE('Cleaned Data'!$J$2:$J$116,7),"")=""),"",INDEX('Cleaned Data'!$A$2:$A$116,MATCH(LARGE('Cleaned Data'!$J$2:$J$116,7),'Cleaned Data'!$J$2:$J$116,0))) -> 53Pcs/Set Yarn Knitting Crochet Hooks With Bag - Fortune Cat | C24: =IF($B24="","",INDEX('Cleaned Data'!$I$2:$I$116,MATCH(LARGE('Cleaned Data'!$J$2:$J$116,7),'Cleaned Data'!$J$2:$J$116,0))) -> 4.7 | D24: =IF($B18="","",INDEX('Cleaned Data'!$G$2:$G$116,MATCH(LARGE('Cleaned Data'!$J$2:$J$116,7),'Cleaned Data'!$J$2:$J$116,0))) -> 20 | E24: =IF($B18="","",INDEX('Cleaned Data'!$B$2:$B$116,MATCH(LARGE('Cleaned Data'!$J$2:$J$116,7),'Cleaned Data'!$J$2:$J$116,0))) -> 1940 | F24: =IF($B18="","",INDEX('Cleaned Data'!$F$2:$F$116,MATCH(LARGE('Cleaned Data'!$J$2:$J$116,7),'Cleaned Data'!$J$2:$J$116,0))) -> 27
A25: 8 | B25: =IF(OR($E$16<8,IFERROR(LARGE('Cleaned Data'!$J$2:$J$116,8),"")=""),"",INDEX('Cleaned Data'!$A$2:$A$116,MATCH(LARGE('Cleaned Data'!$J$2:$J$116,8),'Cleaned Data'!$J$2:$J$116,0))) -> 12 Litre Insulated Lunch Box Grey | C25: =IF($B25="","",INDEX('Cleaned Data'!$I$2:$I$116,MATCH(LARGE('Cleaned Data'!$J$2:$J$116,8),'Cleaned Data'!$J$2:$J$116,0))) -> 4.7 | D25: =IF($B18="","",INDEX('Cleaned Data'!$G$2:$G$116,MATCH(LARGE('Cleaned Data'!$J$2:$J$116,8),'Cleaned Data'!$J$2:$J$116,0))) -> 12 | E25: =IF($B18="","",INDEX('Cleaned Data'!$B$2:$B$116,MATCH(LARGE('Cleaned Data'!$J$2:$J$116,8),'Cleaned Data'!$J$2:$J$116,0))) -> 980 | F25: =IF($B18="","",INDEX('Cleaned Data'!$F$2:$F$116,MATCH(LARGE('Cleaned Data'!$J$2:$J$116,8),'Cleaned Data'!$J$2:$J$116,0))) -> 34
A26: 9 | B26: =IF(OR($E$16<9,IFERROR(LARGE('Cleaned Data'!$J$2:$J$116,9),"")=""),"",INDEX('Cleaned Data'!$A$2:$A$116,MATCH(LARGE('Cleaned Data'!$J$2:$J$116,9),'Cleaned Data'!$J$2:$J$116,0))) -> 40cm Gold DIY Acrylic Wall Sticker Clock | C26: =IF($B26="","",INDEX('Cleaned Data'!$I$2:$I$116,MATCH(LARGE('Cleaned Data'!$J$2:$J$116,9),'Cleaned Data'!$J$2:$J$116,0))) -> 4.8 | D26: =IF($B18="","",INDEX('Cleaned Data'!$G$2:$G$116,MATCH(LARGE('Cleaned Data'!$J$2:$J$116,9),'Cleaned Data'!$J$2:$J$116,0))) -> 12 | E26: =IF($B18="","",INDEX('Cleaned Data'!$B$2:$B$116,MATCH(LARGE('Cleaned Data'!$J$2:$J$116,9),'Cleaned Data'!$J$2:$J$116,0))) -> 552 | F26: =IF($B18="","",INDEX('Cleaned Data'!$F$2:$F$116,MATCH(LARGE('Cleaned Data'!$J$2:$J$116,9),'Cleaned Data'!$J$2:$J$116,0))) -> 47
A27: 10 | B27: =IF(OR($E$16<10,IFERROR(LARGE('Cleaned Data'!$J$2:$J$116,10),"")=""),"",INDEX('Cleaned Data'!$A$2:$A$116,MATCH(LARGE('Cleaned Data'!$J$2:$J$116,10),'Cleaned Data'!$J$2:$J$116,0))) -> Weighing Scale Digital Bathroom Body Fat Scale USB-Black | C27: =IF($B27="","",INDEX('Cleaned Data'!$I$2:$I$116,MATCH(LARGE('Cleaned Data'!$J$2:$J$116,10),'Cleaned Data'!$J$2:$J$116,0))) -> 4.7 | D27: =IF($B18="","",INDEX('Cleaned Data'!$G$2:$G$116,MATCH(LARGE('Cleaned Data'!$J$2:$J$116,10),'Cleaned Data'!$J$2:$J$116,0))) -> 7 | E27: =IF($B18="","",INDEX('Cleaned Data'!$B$2:$B$116,MATCH(LARGE('Cleaned Data'!$J$2:$J$116,10),'Cleaned Data'!$J$2:$J$116,0))) -> 1580 | F27: =IF($B18="","",INDEX('Cleaned Data'!$F$2:$F$116,MATCH(LARGE('Cleaned Data'!$J$2:$J$116,10),'Cleaned Data'!$J$2:$J$116,0))) -> 37
A30: PRODUCTS THAT MAY NEED A DIFFERENT PRICING MARKETING STRATEGY
A31: DISCOUNT% >= | B31: 40 | D31: REVIEWS<= | E31: 3 | G31: Show up to: | H31: 10
A32: NUMBER | B32: PRODUCT | C32: DISCOUNT | D32: REVIEWS
A33: 1 | B33: =IF(OR($H$31<1,IFERROR(LARGE('Cleaned Data'!$K$2:$K$116,1),"")=""),"",INDEX('Cleaned Data'!$A$2:$A$116,MATCH(LARGE('Cleaned Data'!$K$2:$K$116,1),'Cleaned Data'!$K$2:$K$116,0))) -> 6 In 1 Bottle Can Opener Multifunctional Easy Opener | C33: =IF(32="","",INDEX('Cleaned Data'!$F$2:$F$116,MATCH(LARGE('Cleaned Data'!$K$2:$K$116,1),'Cleaned Data'!$K$2:$K$116,0))) -> 64 | D33: =IF(E31="","",INDEX('Cleaned Data'!$G$2:$G$116,MATCH(LARGE('Cleaned Data'!$K$2:$K$116,1),'Cleaned Data'!$K$2:$K$116,0))) -> 0
A34: 2 | B34: =IF(OR($H$31<2,IFERROR(LARGE('Cleaned Data'!$K$2:$K$116,2),"")=""),"",INDEX('Cleaned Data'!$A$2:$A$116,MATCH(LARGE('Cleaned Data'!$K$2:$K$116,2),'Cleaned Data'!$K$2:$K$116,0))) -> Creative Owl Shape Keychain Black | C34: =IF(32="","",INDEX('Cleaned Data'!$F$2:$F$116,MATCH(LARGE('Cleaned Data'!$K$2:$K$116,2),'Cleaned Data'!$K$2:$K$116,0))) -> 61 | D34: =IF(E31="","",INDEX('Cleaned Data'!$G$2:$G$116,MATCH(LARGE('Cleaned Data'!$K$2:$K$116,2),'Cleaned Data'!$K$2:$K$116,0))) -> 0
A35: 3 | B35: =IF(OR($H$31<3,IFERROR(LARGE('Cleaned Data'!$K$2:$K$116,3),"")=""),"",INDEX('Cleaned Data'!$A$2:$A$116,MATCH(LARGE('Cleaned Data'!$K$2:$K$116,3),'Cleaned Data'!$K$2:$K$116,0))) -> Simple Metal Dog Art Sculpture Decoration For Home Office | C35: =IF(32="","",INDEX('Cleaned Data'!$F$2:$F$116,MATCH(LARGE('Cleaned Data'!$K$2:$K$116,3),'Cleaned Data'!$K$2:$K$116,0))) -> 55 | D35: =IF(E31="","",INDEX('Cleaned Data'!$G$2:$G$116,MATCH(LARGE('Cleaned Data'!$K$2:$K$116,3),'Cleaned Data'!$K$2:$K$116,0))) -> 0
A36: 4 | B36: =IF(OR($H$31<4,IFERROR(LARGE('Cleaned Data'!$K$2:$K$116,4),"")=""),"",INDEX('Cleaned Data'!$A$2:$A$116,MATCH(LARGE('Cleaned Data'!$K$2:$K$116,4),'Cleaned Data'!$K$2:$K$116,0))) -> Classic Black Cat Cotton Hemp Pillow Case For Home Car | C36: =IF(32="","",INDEX('Cleaned Data'!$F$2:$F$116,MATCH(LARGE('Cleaned Data'!$K$2:$K$116,4),'Cleaned Data'!$K$2:$K$116,0))) -> 53 | D36: =IF(E31="","",INDEX('Cleaned Data'!$G$2:$G$116,MATCH(LARGE('Cleaned Data'!$K$2:$K$116,4),'Cleaned Data'!$K$2:$K$116,0))) -> 2
A37: 5 | B37: =IF(OR($H$31<5,IFERROR(LARGE('Cleaned Data'!$K$2:$K$116,5),"")=""),"",INDEX('Cleaned Data'!$A$2:$A$116,MATCH(LARGE('Cleaned Data'!$K$2:$K$116,5),'Cleaned Data'!$K$2:$K$116,0))) -> Anti-Skid Absorbent Insulation Coaster For Home Office | C37: =IF(32="","",INDEX('Cleaned Data'!$F$2:$F$116,MATCH(LARGE('Cleaned Data'!$K$2:$K$116,5),'Cleaned Data'!$K$2:$K$116,0))) -> 51 | D37: =IF(E31="","",INDEX('Cleaned Data'!$G$2:$G$116,MATCH(LARGE('Cleaned Data'!$K$2:$K$116,5),'Cleaned Data'!$K$2:$K$116,0))) -> 2
A38: 6 | B38: =IF(OR($H$31<6,IFERROR(LARGE('Cleaned Data'!$K$2:$K$116,6),"")=""),"",INDEX('Cleaned Data'!$A$2:$A$116,MATCH(LARGE('Cleaned Data'!$K$2:$K$116,6),'Cleaned Data'!$K$2:$K$116,0))) -> Wall-mounted Sticker Punch-free Plug Fixer | C38: =IF(32="","",INDEX('Cleaned Data'!$F$2:$F$116,MATCH(LARGE('Cleaned Data'!$K$2:$K$116,6),'Cleaned Data'!$K$2:$K$116,0))) -> 50 | D38: =IF(E31="","",INDEX('Cleaned Data'!$G$2:$G$116,MATCH(LARGE('Cleaned Data'!$K$2:$K$116,6),'Cleaned Data'!$K$2:$K$116,0))) -> 1
A39: 7 | B39: =IF(OR($H$31<7,IFERROR(LARGE('Cleaned Data'!$K$2:$K$116,7),"")=""),"",INDEX('Cleaned Data'!$A$2:$A$116,MATCH(LARGE('Cleaned Data'!$K$2:$K$116,7),'Cleaned Data'!$K$2:$K$116,0))) -> 2PCS Ice Silk Square Cushion Cover Pillowcases - 65x65cm | C39: =IF(32="","",INDEX('Cleaned Data'!$F$2:$F$116,MATCH(LARGE('Cleaned Data'!$K$2:$K$116,7),'Cleaned Data'!$K$2:$K$116,0))) -> 50 | D39: =IF(E31="","",INDEX('Cleaned Data'!$G$2:$G$116,MATCH(LARGE('Cleaned Data'!$K$2:$K$116,7),'Cleaned Data'!$K$2:$K$116,0))) -> 0
A40: 8 | B40: =IF(OR($H$31<8,IFERROR(LARGE('Cleaned Data'!$K$2:$K$116,8),"")=""),"",INDEX('Cleaned Data'!$A$2:$A$116,MATCH(LARGE('Cleaned Data'!$K$2:$K$116,8),'Cleaned Data'!$K$2:$K$116,0))) -> Wall Clock With Hidden Safe Box | C40: =IF(32="","",INDEX('Cleaned Data'!$F$2:$F$116,MATCH(LARGE('Cleaned Data'!$K$2:$K$116,8),'Cleaned Data'!$K$2:$K$116,0))) -> 50 | D40: =IF(E31="","",INDEX('Cleaned Data'!$G$2:$G$116,MATCH(LARGE('Cleaned Data'!$K$2:$K$116,8),'Cleaned Data'!$K$2:$K$116,0))) -> 0
A41: 9 | B41: =IF(OR($H$31<9,IFERROR(LARGE('Cleaned Data'!$K$2:$K$116,9),"")=""),"",INDEX('Cleaned Data'!$A$2:$A$116,MATCH(LARGE('Cleaned Data'!$K$2:$K$116,9),'Cleaned Data'!$K$2:$K$116,0))) -> Brush & Paintbrush Cleaning Tool Pink | C41: =IF(32="","",INDEX('Cleaned Data'!$F$2:$F$116,MATCH(LARGE('Cleaned Data'!$K$2:$K$116,9),'Cleaned Data'!$K$2:$K$116,0))) -> 50 | D41: =IF(E31="","",INDEX('Cleaned Data'!$G$2:$G$116,MATCH(LARGE('Cleaned Data'!$K$2:$K$116,9),'Cleaned Data'!$K$2:$K$116,0))) -> 0
A42: 10 | B42: =IF(OR($H$31<10,IFERROR(LARGE('Cleaned Data'!$K$2:$K$116,10),"")=""),"",INDEX('Cleaned Data'!$A$2:$A$116,MATCH(LARGE('Cleaned Data'!$K$2:$K$116,10),'Cleaned Data'!$K$2:$K$116,0))) -> Christmas Elk Fence Yard Lawn Decorations Cute For Holidays | C42: =IF(32="","",INDEX('Cleaned Data'!$F$2:$F$116,MATCH(LARGE('Cleaned Data'!$K$2:$K$116,10),'Cleaned Data'!$K$2:$K$116,0))) -> 50 | D42: =IF(E31="","",INDEX('Cleaned Data'!$G$2:$G$116,MATCH(LARGE('Cleaned Data'!$K$2:$K$116,10),'Cleaned Data'!$K$2:$K$116,0))) -> 0

Sheet README
A1: READ ME & KEY INSIGHTS
B4: 1) How this workbook is organised
B5: • ORIGINAL - the source file, untouched.
B6: • Cleaned Data - formula-driven, analysis-ready version (prices as numbers, discount as %, reviews as positive counts, rating as a number). Every cell is a formula, so if the ORIGINAL tab is ever updated, this whole workbook recalculates.
B7: • Dashboard - KPIs, correlation readouts, two interactive drill-down tables (yellow cells = adjustable filters), and charts.
B8: • This sheet - plain-English answers to the five questions the dashboard was built to answer.
B11: 3) Do bigger discounts bring in more reviews?
B12: Correlation r = -0.14 - Weak/Moderate negative. In plain terms: products with steeper discounts actually tend to collect FEWER reviews - discounting is not translating into engagement.
B14: 4) Do highly-rated products get stronger engagement (more reviews)?
B15: Correlation r = 0.06 - No meaningful relationship. In plain terms: a higher star rating on its own does not reliably pull in more reviews here - rating quality and review volume are largely independent.
B17: 5) Do price and rating move together?
B18: Correlation r = 0.11 - Weak/Moderate positive. In plain terms: higher-priced items do tend to be rated slightly better.
B20: 6) Which products perform best?
... B24: See the 'Products That May Need a Different Pricing / Marketing Strategy' table on the Dashboard. It flags listings carrying a steep discount (adjustable threshold) that still aren't generating reviews - a sign the discount alone isn't creating traction, and the listing may need better photos/copy, category placement, or a rethink of the discount depth itself.
